<sdf version='1.7'>
  <model name='kmriiwa'>
    <link name='kmriiwa_base_footprint'>
      <inertial>
        <pose>0.004567 -0.002315 0.267968 0 -0 0</pose>
        <mass>397.4</mass>
        <inertia>
          <ixx>31.7279</ixx>
          <ixy>0.61484</ixy>
          <ixz>-1.23789</ixz>
          <iyy>47.6408</iyy>
          <iyz>0.62747</iyz>
          <izz>35.3523</izz>
        </inertia>
      </inertial>
      <collision name='kmriiwa_base_footprint_fixed_joint_lump__kmriiwa_base_link_collision'>
        <pose>0 0 0.025 0 -0 0</pose>
        <geometry>
          <mesh>
            <scale>1 1 1</scale>
            <uri>model://kmriiwa_description/meshes/kmp200/KMP200.dae</uri>
          </mesh>
        </geometry>
        <surface>
          <contact>
            <ode/>
          </contact>
          <friction>
            <ode/>
          </friction>
        </surface>
      </collision>
      <collision name='kmriiwa_base_footprint_fixed_joint_lump__kmriiwa_back_left_wheel_link_collision_1'>
        <pose>-0.28 0.1825 0.125 1.57 -0 0</pose>
        <geometry>
          <cylinder>
            <length>0.132</length>
            <radius>0.125</radius>
          </cylinder>
        </geometry>
        <surface>
          <contact>
            <ode/>
          </contact>
          <friction>
            <ode>
              <mu>0</mu>
              <mu2>0</mu2>
            </ode>
          </friction>
        </surface>
      </collision>
      <collision name='kmriiwa_base_footprint_fixed_joint_lump__kmriiwa_back_right_wheel_link_collision_2'>
        <pose>-0.28 -0.1825 0.125 1.57 -0 0</pose>
        <geometry>
          <cylinder>
            <length>0.132</length>
            <radius>0.125</radius>
          </cylinder>
        </geometry>
        <surface>
          <contact>
            <ode/>
          </contact>
          <friction>
            <ode>
              <mu>0</mu>
              <mu2>0</mu2>
            </ode>
          </friction>
        </surface>
      </collision>
      <collision name='kmriiwa_base_footprint_fixed_joint_lump__kmriiwa_riser_flange_link_collision_3'>
        <pose>0.363 -0.184 0.82 0 0 -1.5708</pose>
        <geometry>
          <cylinder>
            <length>0.26</length>
            <radius>0.121</radius>
          </cylinder>
        </geometry>
      </collision>
      <collision name='kmriiwa_base_footprint_fixed_joint_lump__kmriiwa_link_0_collision_4'>
        <pose>0.363 -0.184 0.95 0 0 -1.5708</pose>
        <geometry>
          <mesh>
            <scale>1 1 1</scale>
            <uri>model://kmriiwa_description/meshes/iiwa14/collision/link_0.stl</uri>
          </mesh>
        </geometry>
        <surface>
          <contact>
            <ode/>
          </contact>
          <friction>
            <ode>
              <mu>0.2</mu>
              <mu2>0.2</mu2>
            </ode>
          </friction>
        </surface>
      </collision>
      <collision name='kmriiwa_base_footprint_fixed_joint_lump__kmriiwa_front_left_wheel_link_collision_5'>
        <pose>0.28 0.1825 0.125 1.57 -0 0</pose>
        <geometry>
          <cylinder>
            <length>0.132</length>
            <radius>0.125</radius>
          </cylinder>
        </geometry>
        <surface>
          <contact>
            <ode/>
          </contact>
          <friction>
            <ode>
              <mu>0</mu>
              <mu2>0</mu2>
            </ode>
          </friction>
        </surface>
      </collision>
      <collision name='kmriiwa_base_footprint_fixed_joint_lump__kmriiwa_front_right_wheel_link_collision_6'>
        <pose>0.28 -0.1825 0.125 1.57 -0 0</pose>
        <geometry>
          <cylinder>
            <length>0.132</length>
            <radius>0.125</radius>
          </cylinder>
        </geometry>
        <surface>
          <contact>
            <ode/>
          </contact>
          <friction>
            <ode>
              <mu>0</mu>
              <mu2>0</mu2>
            </ode>
          </friction>
        </surface>
      </collision>
      <collision name='kmriiwa_base_footprint_fixed_joint_lump__kmriiwa_laser_B1_link_collision_7'>
        <pose>0.464 -0.256 0.1418 0 0 -0.7854</pose>
        <geometry>
          <mesh>
            <scale>1 1 1</scale>
            <uri>model://kmriiwa_description/meshes/kmp200/sensors/collision/sick_lms1xx.stl</uri>
          </mesh>
        </geometry>
        <surface>
          <contact>
            <ode/>
          </contact>
          <friction>
            <ode/>
          </friction>
        </surface>
      </collision>
      <collision name='kmriiwa_base_footprint_fixed_joint_lump__kmriiwa_laser_B4_link_collision_8'>
        <pose>-0.464 0.256 0.1418 0 -0 2.3562</pose>
        <geometry>
          <mesh>
            <scale>1 1 1</scale>
            <uri>model://kmriiwa_description/meshes/kmp200/sensors/collision/sick_lms1xx.stl</uri>
          </mesh>
        </geometry>
        <surface>
          <contact>
            <ode/>
          </contact>
          <friction>
            <ode/>
          </friction>
        </surface>
      </collision>
      <visual name='kmriiwa_base_footprint_fixed_joint_lump__kmriiwa_base_link_visual'>
        <pose>0 0 0.025 0 -0 0</pose>
        <geometry>
          <mesh>
            <scale>1 1 1</scale>
            <uri>model://kmriiwa_description/meshes/kmp200/KMP200.dae</uri>
          </mesh>
        </geometry>
        <material>
          <script>
            <name>Gazebo/Grey</name>
            <uri>file://media/materials/scripts/gazebo.material</uri>
          </script>
        </material>
      </visual>
      <visual name='kmriiwa_base_footprint_fixed_joint_lump__kmriiwa_back_left_wheel_link_visual_1'>
        <pose>-0.28 0.1825 0.125 0 -0 0</pose>
        <geometry>
          <mesh>
            <scale>1.06695 1.06695 1.06695</scale>
            <uri>model://kmriiwa_description/meshes/kmp200/wheels/omni_wheel_1.dae</uri>
          </mesh>
        </geometry>
      </visual>
      <visual name='kmriiwa_base_footprint_fixed_joint_lump__kmriiwa_back_right_wheel_link_visual_2'>
        <pose>-0.28 -0.1825 0.125 0 -0 0</pose>
        <geometry>
          <mesh>
            <scale>1.06695 1.06695 1.06695</scale>
            <uri>model://kmriiwa_description/meshes/kmp200/wheels/omni_wheel_1.dae</uri>
          </mesh>
        </geometry>
      </visual>
      <visual name='kmriiwa_base_footprint_fixed_joint_lump__kmriiwa_riser_flange_link_visual_3'>
        <pose>0.363 -0.184 0.82 0 0 -1.5708</pose>
        <geometry>
          <cylinder>
            <length>0.26</length>
            <radius>0.121</radius>
          </cylinder>
        </geometry>
      </visual>
      <visual name='kmriiwa_base_footprint_fixed_joint_lump__kmriiwa_link_0_visual_4'>
        <pose>0.363 -0.184 0.95 0 0 -1.5708</pose>
        <geometry>
          <mesh>
            <scale>1 1 1</scale>
            <uri>model://kmriiwa_description/meshes/iiwa14/visual/link_0.stl</uri>
          </mesh>
        </geometry>
        <material>
          <script>
            <name>Gazebo/Grey</name>
            <uri>file://media/materials/scripts/gazebo.material</uri>
          </script>
        </material>
      </visual>
      <visual name='kmriiwa_base_footprint_fixed_joint_lump__kmriiwa_front_left_wheel_link_visual_5'>
        <pose>0.28 0.1825 0.125 0 -0 0</pose>
        <geometry>
          <mesh>
            <scale>1.06695 1.06695 1.06695</scale>
            <uri>model://kmriiwa_description/meshes/kmp200/wheels/omni_wheel_1.dae</uri>
          </mesh>
        </geometry>
      </visual>
      <visual name='kmriiwa_base_footprint_fixed_joint_lump__kmriiwa_front_right_wheel_link_visual_6'>
        <pose>0.28 -0.1825 0.125 0 -0 0</pose>
        <geometry>
          <mesh>
            <scale>1.06695 1.06695 1.06695</scale>
            <uri>model://kmriiwa_description/meshes/kmp200/wheels/omni_wheel_1.dae</uri>
          </mesh>
        </geometry>
      </visual>
      <visual name='kmriiwa_base_footprint_fixed_joint_lump__kmriiwa_laser_B1_link_visual_7'>
        <pose>0.464 -0.256 0.1418 3.1413 -0 -0.7854</pose>
        <geometry>
          <mesh>
            <scale>1 1 1</scale>
            <uri>model://kmriiwa_description/meshes/kmp200/sensors/visual/sick_lms1xx.dae</uri>
          </mesh>
        </geometry>
      </visual>
      <visual name='kmriiwa_base_footprint_fixed_joint_lump__kmriiwa_laser_B4_link_visual_8'>
        <pose>-0.464 0.256 0.1418 -3.14159 0.000293 2.35591</pose>
        <geometry>
          <mesh>
            <scale>1 1 1</scale>
            <uri>model://kmriiwa_description/meshes/kmp200/sensors/visual/sick_lms1xx.dae</uri>
          </mesh>
        </geometry>
      </visual>
      <sensor name='sensor_B1' type='ray'>
        <always_on>1</always_on>
        <visualize>1</visualize>
        <update_rate>10</update_rate>
        <ray>
          <scan>
            <horizontal>
              <samples>640</samples>
              <resolution>1</resolution>
              <min_angle>-2.30383</min_angle>
              <max_angle>2.30383</max_angle>
            </horizontal>
          </scan>
          <range>
            <min>0.12</min>
            <max>15</max>
            <resolution>0.01</resolution>
          </range>
          <noise>
            <type>gaussian</type>
            <mean>0</mean>
            <stddev>0.01</stddev>
          </noise>
        </ray>
        <plugin name='gazebo_sensor_B1_controller' filename='libgazebo_ros_laser.so'>
          <robotNamespace>/</robotNamespace>
          <topicName>/kmriiwa/base/state/LaserB1Scan</topicName>
          <output_type>sensor_msgs/LaserScan</output_type>
          <frameName>kmriiwa_laser_B1_link</frameName>
        </plugin>
        <pose>0.464 -0.256 0.1418 0 0 -0.7854</pose>
      </sensor>
      <sensor name='sensor_B4' type='ray'>
        <always_on>1</always_on>
        <visualize>1</visualize>
        <update_rate>10</update_rate>
        <ray>
          <scan>
            <horizontal>
              <samples>640</samples>
              <resolution>1</resolution>
              <min_angle>-2.30383</min_angle>
              <max_angle>2.30383</max_angle>
            </horizontal>
          </scan>
          <range>
            <min>0.12</min>
            <max>15</max>
            <resolution>0.01</resolution>
          </range>
          <noise>
            <type>gaussian</type>
            <mean>0</mean>
            <stddev>0.01</stddev>
          </noise>
        </ray>
        <plugin name='gazebo_sensor_B4_controller' filename='libgazebo_ros_laser.so'>
          <robotNamespace>/</robotNamespace>
          <topicName>/kmriiwa/base/state/LaserB4Scan</topicName>
          <output_type>sensor_msgs/LaserScan</output_type>
          <frameName>kmriiwa_laser_B4_link</frameName>
        </plugin>
        <pose>-0.464 0.256 0.1418 0 -0 2.3562</pose>
      </sensor>
      <surface>
        <contact>
          <collide_without_contact>1</collide_without_contact>
        </contact>
      </surface>
      <surface>
        <contact>
          <collide_without_contact>1</collide_without_contact>
        </contact>
      </surface>
      <surface>
        <contact>
          <collide_without_contact>1</collide_without_contact>
        </contact>
      </surface>
      <surface>
        <contact>
          <collide_without_contact>1</collide_without_contact>
        </contact>
      </surface>
    </link>
    <joint name='kmriiwa_joint_1' type='revolute'>
      <pose relative_to='kmriiwa_base_footprint'>0.363 -0.184 1.1075 0 0 -1.5708</pose>
      <parent>kmriiwa_base_footprint</parent>
      <child>kmriiwa_link_1</child>
      <axis>
        <xyz>0 0 1</xyz>
        <limit>
          <lower>-2.96706</lower>
          <upper>2.96706</upper>
          <effort>300</effort>
          <velocity>10</velocity>
        </limit>
        <dynamics>
          <damping>0.5</damping>
          <friction>0</friction>
          <spring_reference>0</spring_reference>
          <spring_stiffness>0</spring_stiffness>
        </dynamics>
      </axis>
    </joint>
    <link name='kmriiwa_link_1'>
      <pose relative_to='kmriiwa_joint_1'>0 0 0 0 -0 0</pose>
      <inertial>
        <pose>0 -0.03 0.12 0 -0 0</pose>
        <mass>4</mass>
        <inertia>
          <ixx>0.1</ixx>
          <ixy>0</ixy>
          <ixz>0</ixz>
          <iyy>0.09</iyy>
          <iyz>0</iyz>
          <izz>0.02</izz>
        </inertia>
      </inertial>
      <collision name='kmriiwa_link_1_collision'>
        <pose>0 0 0 0 -0 0</pose>
        <geometry>
          <mesh>
            <scale>1 1 1</scale>
            <uri>model://kmriiwa_description/meshes/iiwa14/collision/link_1.stl</uri>
          </mesh>
        </geometry>
        <surface>
          <contact>
            <ode/>
          </contact>
          <friction>
            <ode>
              <mu>0.2</mu>
              <mu2>0.2</mu2>
            </ode>
          </friction>
        </surface>
      </collision>
      <visual name='kmriiwa_link_1_visual'>
        <pose>0 0 0 0 -0 0</pose>
        <geometry>
          <mesh>
            <scale>1 1 1</scale>
            <uri>model://kmriiwa_description/meshes/iiwa14/visual/link_1.stl</uri>
          </mesh>
        </geometry>
        <material>
          <script>
            <name>Gazebo/Orange</name>
            <uri>file://media/materials/scripts/gazebo.material</uri>
          </script>
        </material>
      </visual>
    </link>
    <joint name='kmriiwa_joint_2' type='revolute'>
      <pose relative_to='kmriiwa_link_1'>0 0 0.2025 1.5708 -0 3.14159</pose>
      <parent>kmriiwa_link_1</parent>
      <child>kmriiwa_link_2</child>
      <axis>
        <xyz>0 0 1</xyz>
        <limit>
          <lower>-2.0944</lower>
          <upper>2.0944</upper>
          <effort>300</effort>
          <velocity>10</velocity>
        </limit>
        <dynamics>
          <damping>0.5</damping>
          <friction>0</friction>
          <spring_reference>0</spring_reference>
          <spring_stiffness>0</spring_stiffness>
        </dynamics>
      </axis>
    </joint>
    <link name='kmriiwa_link_2'>
      <pose relative_to='kmriiwa_joint_2'>0 0 0 0 -0 0</pose>
      <inertial>
        <pose>0.0003 0.059 0.042 0 -0 0</pose>
        <mass>4</mass>
        <inertia>
          <ixx>0.05</ixx>
          <ixy>0</ixy>
          <ixz>0</ixz>
          <iyy>0.018</iyy>
          <iyz>0</iyz>
          <izz>0.044</izz>
        </inertia>
      </inertial>
      <collision name='kmriiwa_link_2_collision'>
        <pose>0 0 0 0 -0 0</pose>
        <geometry>
          <mesh>
            <scale>1 1 1</scale>
            <uri>model://kmriiwa_description/meshes/iiwa14/collision/link_2.stl</uri>
          </mesh>
        </geometry>
        <surface>
          <contact>
            <ode/>
          </contact>
          <friction>
            <ode>
              <mu>0.2</mu>
              <mu2>0.2</mu2>
            </ode>
          </friction>
        </surface>
      </collision>
      <visual name='kmriiwa_link_2_visual'>
        <pose>0 0 0 0 -0 0</pose>
        <geometry>
          <mesh>
            <scale>1 1 1</scale>
            <uri>model://kmriiwa_description/meshes/iiwa14/visual/link_2.stl</uri>
          </mesh>
        </geometry>
        <material>
          <script>
            <name>Gazebo/Orange</name>
            <uri>file://media/materials/scripts/gazebo.material</uri>
          </script>
        </material>
      </visual>
    </link>
    <joint name='kmriiwa_joint_3' type='revolute'>
      <pose relative_to='kmriiwa_link_2'>0 0.2045 0 1.5708 -0 3.14159</pose>
      <parent>kmriiwa_link_2</parent>
      <child>kmriiwa_link_3</child>
      <axis>
        <xyz>0 0 1</xyz>
        <limit>
          <lower>-2.96706</lower>
          <upper>2.96706</upper>
          <effort>300</effort>
          <velocity>10</velocity>
        </limit>
        <dynamics>
          <damping>0.5</damping>
          <friction>0</friction>
          <spring_reference>0</spring_reference>
          <spring_stiffness>0</spring_stiffness>
        </dynamics>
      </axis>
    </joint>
    <link name='kmriiwa_link_3'>
      <pose relative_to='kmriiwa_joint_3'>0 0 0 0 -0 0</pose>
      <inertial>
        <pose>0 0.03 0.13 0 -0 0</pose>
        <mass>3</mass>
        <inertia>
          <ixx>0.08</ixx>
          <ixy>0</ixy>
          <ixz>0</ixz>
          <iyy>0.075</iyy>
          <iyz>0</iyz>
          <izz>0.01</izz>
        </inertia>
      </inertial>
      <collision name='kmriiwa_link_3_collision'>
        <pose>0 0 0 0 -0 0</pose>
        <geometry>
          <mesh>
            <scale>1 1 1</scale>
            <uri>model://kmriiwa_description/meshes/iiwa14/collision/link_3.stl</uri>
          </mesh>
        </geometry>
        <surface>
          <contact>
            <ode/>
          </contact>
          <friction>
            <ode>
              <mu>0.2</mu>
              <mu2>0.2</mu2>
            </ode>
          </friction>
        </surface>
      </collision>
      <visual name='kmriiwa_link_3_visual'>
        <pose>0 0 0 0 -0 0</pose>
        <geometry>
          <mesh>
            <scale>1 1 1</scale>
            <uri>model://kmriiwa_description/meshes/iiwa14/visual/link_3.stl</uri>
          </mesh>
        </geometry>
        <material>
          <script>
            <name>Gazebo/Orange</name>
            <uri>file://media/materials/scripts/gazebo.material</uri>
          </script>
        </material>
      </visual>
    </link>
    <joint name='kmriiwa_joint_4' type='revolute'>
      <pose relative_to='kmriiwa_link_3'>0 0 0.2155 1.5708 -0 0</pose>
      <parent>kmriiwa_link_3</parent>
      <child>kmriiwa_link_4</child>
      <axis>
        <xyz>0 0 1</xyz>
        <limit>
          <lower>-2.0944</lower>
          <upper>2.0944</upper>
          <effort>300</effort>
          <velocity>10</velocity>
        </limit>
        <dynamics>
          <damping>0.5</damping>
          <friction>0</friction>
          <spring_reference>0</spring_reference>
          <spring_stiffness>0</spring_stiffness>
        </dynamics>
      </axis>
    </joint>
    <link name='kmriiwa_link_4'>
      <pose relative_to='kmriiwa_joint_4'>0 0 0 0 -0 0</pose>
      <inertial>
        <pose>0 0.067 0.034 0 -0 0</pose>
        <mass>2.7</mass>
        <inertia>
          <ixx>0.03</ixx>
          <ixy>0</ixy>
          <ixz>0</ixz>
          <iyy>0.01</iyy>
          <iyz>0</iyz>
          <izz>0.029</izz>
        </inertia>
      </inertial>
      <collision name='kmriiwa_link_4_collision'>
        <pose>0 0 0 0 -0 0</pose>
        <geometry>
          <mesh>
            <scale>1 1 1</scale>
            <uri>model://kmriiwa_description/meshes/iiwa14/collision/link_4.stl</uri>
          </mesh>
        </geometry>
        <surface>
          <contact>
            <ode/>
          </contact>
          <friction>
            <ode>
              <mu>0.2</mu>
              <mu2>0.2</mu2>
            </ode>
          </friction>
        </surface>
      </collision>
      <visual name='kmriiwa_link_4_visual'>
        <pose>0 0 0 0 -0 0</pose>
        <geometry>
          <mesh>
            <scale>1 1 1</scale>
            <uri>model://kmriiwa_description/meshes/iiwa14/visual/link_4.stl</uri>
          </mesh>
        </geometry>
        <material>
          <script>
            <name>Gazebo/Orange</name>
            <uri>file://media/materials/scripts/gazebo.material</uri>
          </script>
        </material>
      </visual>
    </link>
    <joint name='kmriiwa_joint_5' type='revolute'>
      <pose relative_to='kmriiwa_link_4'>0 0.1845 0 1.5708 0 3.14159</pose>
      <parent>kmriiwa_link_4</parent>
      <child>kmriiwa_link_5</child>
      <axis>
        <xyz>0 0 1</xyz>
        <limit>
          <lower>-2.96706</lower>
          <upper>2.96706</upper>
          <effort>300</effort>
          <velocity>10</velocity>
        </limit>
        <dynamics>
          <damping>0.5</damping>
          <friction>0</friction>
          <spring_reference>0</spring_reference>
          <spring_stiffness>0</spring_stiffness>
        </dynamics>
      </axis>
    </joint>
    <link name='kmriiwa_link_5'>
      <pose relative_to='kmriiwa_joint_5'>0 0 0 0 -0 0</pose>
      <inertial>
        <pose>0.0001 0.021 0.076 0 -0 0</pose>
        <mass>1.7</mass>
        <inertia>
          <ixx>0.02</ixx>
          <ixy>0</ixy>
          <ixz>0</ixz>
          <iyy>0.018</iyy>
          <iyz>0</iyz>
          <izz>0.005</izz>
        </inertia>
      </inertial>
      <collision name='kmriiwa_link_5_collision'>
        <pose>0 0 0 0 -0 0</pose>
        <geometry>
          <mesh>
            <scale>1 1 1</scale>
            <uri>model://kmriiwa_description/meshes/iiwa14/collision/link_5.stl</uri>
          </mesh>
        </geometry>
        <surface>
          <contact>
            <ode/>
          </contact>
          <friction>
            <ode>
              <mu>0.2</mu>
              <mu2>0.2</mu2>
            </ode>
          </friction>
        </surface>
      </collision>
      <visual name='kmriiwa_link_5_visual'>
        <pose>0 0 0 0 -0 0</pose>
        <geometry>
          <mesh>
            <scale>1 1 1</scale>
            <uri>model://kmriiwa_description/meshes/iiwa14/visual/link_5.stl</uri>
          </mesh>
        </geometry>
        <material>
          <script>
            <name>Gazebo/Orange</name>
            <uri>file://media/materials/scripts/gazebo.material</uri>
          </script>
        </material>
      </visual>
    </link>
    <joint name='kmriiwa_joint_6' type='revolute'>
      <pose relative_to='kmriiwa_link_5'>0 0 0.2155 1.5708 -0 0</pose>
      <parent>kmriiwa_link_5</parent>
      <child>kmriiwa_link_6</child>
      <axis>
        <xyz>0 0 1</xyz>
        <limit>
          <lower>-2.0944</lower>
          <upper>2.0944</upper>
          <effort>300</effort>
          <velocity>10</velocity>
        </limit>
        <dynamics>
          <damping>0.5</damping>
          <friction>0</friction>
          <spring_reference>0</spring_reference>
          <spring_stiffness>0</spring_stiffness>
        </dynamics>
      </axis>
    </joint>
    <link name='kmriiwa_link_6'>
      <pose relative_to='kmriiwa_joint_6'>0 0 0 0 -0 0</pose>
      <inertial>
        <pose>0 0.0006 0.0004 0 -0 0</pose>
        <mass>1.8</mass>
        <inertia>
          <ixx>0.005</ixx>
          <ixy>0</ixy>
          <ixz>0</ixz>
          <iyy>0.0036</iyy>
          <iyz>0</iyz>
          <izz>0.0047</izz>
        </inertia>
      </inertial>
      <collision name='kmriiwa_link_6_collision'>
        <pose>0 0 0 0 -0 0</pose>
        <geometry>
          <mesh>
            <scale>1 1 1</scale>
            <uri>model://kmriiwa_description/meshes/iiwa14/collision/link_6.stl</uri>
          </mesh>
        </geometry>
        <surface>
          <contact>
            <ode/>
          </contact>
          <friction>
            <ode>
              <mu>0.2</mu>
              <mu2>0.2</mu2>
            </ode>
          </friction>
        </surface>
      </collision>
      <visual name='kmriiwa_link_6_visual'>
        <pose>0 0 0 0 -0 0</pose>
        <geometry>
          <mesh>
            <scale>1 1 1</scale>
            <uri>model://kmriiwa_description/meshes/iiwa14/visual/link_6.stl</uri>
          </mesh>
        </geometry>
        <material>
          <script>
            <name>Gazebo/Orange</name>
            <uri>file://media/materials/scripts/gazebo.material</uri>
          </script>
        </material>
      </visual>
    </link>
    <joint name='kmriiwa_joint_7' type='revolute'>
      <pose relative_to='kmriiwa_link_6'>0 0.081 0 1.5708 0 3.14159</pose>
      <parent>kmriiwa_link_6</parent>
      <child>kmriiwa_link_7</child>
      <axis>
        <xyz>0 0 1</xyz>
        <limit>
          <lower>-3.05433</lower>
          <upper>3.05433</upper>
          <effort>300</effort>
          <velocity>10</velocity>
        </limit>
        <dynamics>
          <damping>0.5</damping>
          <friction>0</friction>
          <spring_reference>0</spring_reference>
          <spring_stiffness>0</spring_stiffness>
        </dynamics>
      </axis>
      <physics>
        <provide_feedback>1</provide_feedback>
        <ode>
          <limit>
            <cfm>0</cfm>
            <erp>0.2</erp>
          </limit>
          <provide_feedback>1</provide_feedback>
        </ode>
      </physics>
    </joint>
    <link name='kmriiwa_link_7'>
      <pose relative_to='kmriiwa_joint_7'>0 0 0 0 -0 0</pose>
      <inertial>
        <pose>0 0 0.02 0 -0 0</pose>
        <mass>0.3</mass>
        <inertia>
          <ixx>0.001</ixx>
          <ixy>0</ixy>
          <ixz>0</ixz>
          <iyy>0.001</iyy>
          <iyz>0</iyz>
          <izz>0.001</izz>
        </inertia>
      </inertial>
      <collision name='kmriiwa_link_7_collision'>
        <pose>0 0 0 0 -0 0</pose>
        <geometry>
          <mesh>
            <scale>1 1 1</scale>
            <uri>model://kmriiwa_description/meshes/iiwa14/collision/link_7.stl</uri>
          </mesh>
        </geometry>
        <surface>
          <contact>
            <ode/>
          </contact>
          <friction>
            <ode>
              <mu>0.2</mu>
              <mu2>0.2</mu2>
            </ode>
          </friction>
        </surface>
      </collision>
      <visual name='kmriiwa_link_7_visual'>
        <pose>0 0 0 0 -0 0</pose>
        <geometry>
          <mesh>
            <scale>1 1 1</scale>
            <uri>model://kmriiwa_description/meshes/iiwa14/visual/link_7.stl</uri>
          </mesh>
        </geometry>
        <material>
          <script>
            <name>Gazebo/Grey</name>
            <uri>file://media/materials/scripts/gazebo.material</uri>
          </script>
        </material>
      </visual>
    </link>
    <plugin name='ros_force_based_move' filename='libgazebo_ros_force_based_move.so'>
      <robotNamespace>/kmriiwa</robotNamespace>
      <commandTopic>base/command/cmd_vel</commandTopic>
      <odometryTopic>base/state/odom</odometryTopic>
      <robotBaseFrame>kmriiwa_base_footprint</robotBaseFrame>
      <publishOdometryTf>1</publishOdometryTf>
      <odometryFrame>kmriiwa_odom</odometryFrame>
      <odometryRate>20.0</odometryRate>
      <yaw_velocity_p_gain>500</yaw_velocity_p_gain>
      <x_velocity_p_gain>1000</x_velocity_p_gain>
      <y_velocity_p_gain>1000</y_velocity_p_gain>
    </plugin>
    <plugin name='ft_sensor' filename='libgazebo_ros_ft_sensor.so'>
      <updateRate>50.0</updateRate>
      <topicName>/kmriiwa/state/CartesianWrench</topicName>
      <jointName>kmriiwa_joint_7</jointName>
    </plugin>
    <plugin name='gazebo_ros_control' filename='libgazebo_ros_control.so'>
      <robotNamespace>/kmriiwa/arm</robotNamespace>
      <robotParam>/kmriiwa/robot_description</robotParam>
    </plugin>
    <frame name='kmriiwa_back_left_wheel_joint' attached_to='kmriiwa_base_link'>
      <pose>-0.28 0.1825 0.1 0 -0 0</pose>
    </frame>
    <frame name='kmriiwa_back_left_wheel_link' attached_to='kmriiwa_back_left_wheel_joint'/>
    <frame name='kmriiwa_back_right_wheel_joint' attached_to='kmriiwa_base_link'>
      <pose>-0.28 -0.1825 0.1 0 -0 0</pose>
    </frame>
    <frame name='kmriiwa_back_right_wheel_link' attached_to='kmriiwa_back_right_wheel_joint'/>
    <frame name='kmriiwa_riser_flange_link_kmriiwa_joint' attached_to='kmriiwa_riser_flange_link'>
      <pose>0 0 0.13 0 -0 0</pose>
    </frame>
    <frame name='kmriiwa_link_0' attached_to='kmriiwa_riser_flange_link_kmriiwa_joint'/>
    <frame name='kmriiwa_joint_ee' attached_to='kmriiwa_link_7'>
      <pose>0 0 0.045 0 -0 0</pose>
    </frame>
    <frame name='kmriiwa_link_ee' attached_to='kmriiwa_joint_ee'/>
    <frame name='kmriiwa_base_top_riser_flange_joint' attached_to='kmriiwa_base_top_link'>
      <pose>0.363 -0.184 0.12 0 0 -1.5708</pose>
    </frame>
    <frame name='kmriiwa_riser_flange_link' attached_to='kmriiwa_base_top_riser_flange_joint'/>
    <frame name='kmriiwa_base_link_to_top' attached_to='kmriiwa_base_link'>
      <pose>0 0 0.675 0 -0 0</pose>
    </frame>
    <frame name='kmriiwa_base_top_link' attached_to='kmriiwa_base_link_to_top'/>
    <frame name='kmriiwa_front_left_wheel_joint' attached_to='kmriiwa_base_link'>
      <pose>0.28 0.1825 0.1 0 -0 0</pose>
    </frame>
    <frame name='kmriiwa_front_left_wheel_link' attached_to='kmriiwa_front_left_wheel_joint'/>
    <frame name='kmriiwa_front_right_wheel_joint' attached_to='kmriiwa_base_link'>
      <pose>0.28 -0.1825 0.1 0 -0 0</pose>
    </frame>
    <frame name='kmriiwa_front_right_wheel_link' attached_to='kmriiwa_front_right_wheel_joint'/>
    <frame name='kmriiwa_laser_B1_joint' attached_to='kmriiwa_base_link'>
      <pose>0.464 -0.256 0.1168 0 0 -0.7854</pose>
    </frame>
    <frame name='kmriiwa_laser_B1_link' attached_to='kmriiwa_laser_B1_joint'/>
    <frame name='kmriiwa_laser_B4_joint' attached_to='kmriiwa_base_link'>
      <pose>-0.464 0.256 0.1168 0 -0 2.3562</pose>
    </frame>
    <frame name='kmriiwa_laser_B4_link' attached_to='kmriiwa_laser_B4_joint'/>
    <frame name='kmriiwa_footprint_to_base_link' attached_to='kmriiwa_base_footprint'>
      <pose>0 0 0.025 0 -0 0</pose>
    </frame>
    <frame name='kmriiwa_base_link' attached_to='kmriiwa_footprint_to_base_link'/>
  </model>
</sdf>
